<?xml version="1.0"?>

<robot name="robot_base" xmlns:xacro="http://www.ros.org/wiki/xacro">

  <!-- BASE LINK -->

  <link name="base_link">

  </link>

  <!-- BASE_FOOTPRINT LINK -->

  <joint name="base_footprint_joint" type="fixed">
    <parent link="base_link" />
    <child link="base_footprint" />
    <origin xyz="0 0 0" rpy="0 0 0" />
  </joint>

  <link name="base_footprint">
    <inertial>
      <origin xyz="0.0030946 4.78250032638821E-11 0.053305" rpy="0 0 0" />
      <mass value="47.873" />
      <inertia
        ixx="0.774276574699151"
        ixy="-1.03781944357671E-10"
        ixz="0.00763014265820928"
        iyy="1.64933255189991"
        iyz="1.09578155845563E-12"
        izz="2.1239326987473" />
    </inertial>
    <visual>
      <origin xyz="0 0 0" rpy="1.5707963267949 0 3.14" />
      <geometry>
        <mesh
          filename="file://$(find mobile_manipulator_body)/meshes/robot_base.stl" />
      </geometry>
      <material name="">
        <color rgba="0.79216 0.81961 0.93333 1" />
      </material>
    </visual>
    <collision>
      <origin xyz="0 0 0" rpy="1.5707963267949 0 3.14" />
      <geometry>
        <mesh
          filename="file://$(find mobile_manipulator_body)/meshes/robot_base.stl" />
      </geometry>
    </collision>
  </link>

  <link name="front_left_wheel">
    <inertial>
      <origin xyz="-4.1867E-18 0.0068085 -1.65658661799998E-18" rpy="0 0 0" />
      <mass value="2.6578" />
      <inertia
        ixx="0.00856502765719703"
        ixy="1.5074118157338E-19"
        ixz="-4.78150098725052E-19"
        iyy="0.013670640432096"
        iyz="-2.68136447099727E-19"
        izz="0.00856502765719703" />
    </inertial>
    <visual>
      <origin xyz="0 0 0" rpy="1.5707963267949 0 0" />
      <geometry>
        <mesh filename="file://$(find mobile_manipulator_body)/meshes/wheel.stl" />
      </geometry>
      <material name="">
        <color
          rgba="0.79216 0.81961 0.93333 1" />
      </material>
    </visual>
    <collision>
      <origin xyz="0 0 0" rpy="1.5707963267949 0 0" />
      <geometry>
        <mesh filename="file://$(find mobile_manipulator_body)/meshes/wheel.stl" />
      </geometry>
    </collision>
  </link>

  <link name="front_right_wheel">
    <inertial>
      <origin xyz="-4.1867E-18 0.0068085 -1.65658661799998E-18" rpy="0 0 0" />
      <mass value="2.6578" />
      <inertia
        ixx="0.00856502765719703"
        ixy="1.5074118157338E-19"
        ixz="-4.78150098725052E-19"
        iyy="0.013670640432096"
        iyz="-2.68136447099727E-19"
        izz="0.00856502765719703" />
    </inertial>
    <visual>
      <origin xyz="0 0 0" rpy="1.5707963267949 0 0" />
      <geometry>
        <mesh filename="file://$(find mobile_manipulator_body)/meshes/wheel.stl" />
      </geometry>
      <material name="">
        <color
          rgba="0.79216 0.81961 0.93333 1" />
      </material>
    </visual>
    <collision>
      <origin xyz="0 0 0" rpy="1.5707963267949 0 0" />
      <geometry>
        <mesh filename="file://$(find mobile_manipulator_body)/meshes/wheel.stl" />
      </geometry>
    </collision>
  </link>

  <link name="rear_left_wheel">
    <inertial>
      <origin xyz="-4.1867E-18 0.0068085 -1.65658661799998E-18" rpy="0 0 0" />
      <mass
        value="2.6578" />
      <inertia
        ixx="0.00856502765719703"
        ixy="1.5074118157338E-19"
        ixz="-4.78150098725052E-19"
        iyy="0.013670640432096"
        iyz="-2.68136447099727E-19"
        izz="0.00856502765719703" />
    </inertial>
    <visual>
      <origin xyz="0 0 0" rpy="1.5707963267949 0 0" />
      <geometry>
        <mesh filename="file://$(find mobile_manipulator_body)/meshes/wheel.stl" />
      </geometry>
      <material name="">
        <color rgba="0.79216 0.81961 0.93333 1" />
      </material>
    </visual>
    <collision>
      <origin xyz="0 0 0" rpy="1.5707963267949 0 0" />
      <geometry>
        <mesh filename="file://$(find mobile_manipulator_body)/meshes/wheel.stl" />
      </geometry>
    </collision>
  </link>

  <link name="rear_right_wheel">
    <inertial>
      <origin xyz="-4.1867E-18 0.0068085 -1.65658661799998E-18" rpy="0 0 0" />
      <mass value="2.6578" />
      <inertia
        ixx="0.00856502765719703"
        ixy="1.5074118157338E-19"
        ixz="-4.78150098725052E-19"
        iyy="0.013670640432096"
        iyz="-2.68136447099727E-19"
        izz="0.00856502765719703" />
    </inertial>
    <visual>
      <origin xyz="0 0 0" rpy="1.5707963267949 0 0" />
      <geometry>
        <mesh filename="file://$(find mobile_manipulator_body)/meshes/wheel.stl" />
      </geometry>
      <material name="">
        <color rgba="0.79216 0.81961 0.93333 1" />
      </material>
    </visual>
    <collision>
      <origin xyz="0 0 0" rpy="1.5707963267949 0 0" />
      <geometry>
        <mesh filename="file://$(find mobile_manipulator_body)/meshes/wheel.stl" />
      </geometry>
    </collision>
  </link>

  <link name="imu_link" />

  <joint name="imu_joint" type="fixed">
    <parent link="base_link" />
    <child link="imu_link" />
    <origin xyz="-0.032 0 0.068" rpy="0 0 0" />
  </joint>

  <link name="base_scan">
    <visual>
      <origin xyz="0 0 0.0" rpy="0 0 0" />
      <geometry>
        <mesh filename="file://$(find mobile_manipulator_body)/meshes/lds.dae"
          scale="0.001 0.001 0.001" />
      </geometry>
      <!-- <material name="dark" /> -->
      <color rgba="1 1 1 1" />
    </visual>

    <collision>
      <origin xyz="0.015 0 -0.0065" rpy="0 0 0" />
      <geometry>
        <cylinder length="0.0315" radius="0.055" />
      </geometry>
    </collision>

    <inertial>
      <mass value="0.114" />
      <origin xyz="0 0 0" />
      <inertia ixx="0.001" ixy="0.0" ixz="0.0" iyy="0.001" iyz="0.0" izz="0.001" />
    </inertial>
  </link>

  <joint name="scan_joint" type="fixed">
    <parent link="base_link" />
    <child link="base_scan" />
    <origin xyz="-0.032 0 0.172" rpy="0 0 0" />
  </joint>

  <gazebo reference="base_scan">
    <material>Gazebo/Red</material>

    <sensor name="laser" type="ray">
      <pose> 0 0 0 0 0 0 </pose>
      <always_on>true</always_on>
      <visualize>true</visualize>
      <update_rate>5</update_rate>
      <ray>
        <scan>
          <horizontal>
            <samples>360</samples>
            <min_angle>0.00</min_angle>
            <max_angle>6.28000</max_angle>
          </horizontal>
        </scan>
        <range>
          <min>0.12</min>
          <max>6</max>
        </range>
        <noise>
          <type>gaussian</type>
          <mean>0.0</mean>
          <stddev>0.01</stddev>
        </noise>
      </ray>
      <plugin name="laser_controller" filename="libgazebo_ros_ray_sensor.so">
        <ros>
          <remapping>~/out:=scan</remapping>
        </ros>
        <output_type>sensor_msgs/LaserScan</output_type>
        <!-- <frame_name>laser_frame</frame_name> -->
        <frame_name>base_scan</frame_name>
      </plugin>
    </sensor>
  </gazebo>


<!--  -->

  <joint name="camera_joint" type="fixed">
    <parent link="base_link"/>
    <child link="camera_link"/>
    <origin xyz="0.325 0 0.15" rpy="0 0 0"/>
  </joint>
  <link name="camera_link">
      <visual>
      <origin xyz="0 0 0.0" rpy="0 1.57 0" />
      <geometry>
        <mesh filename="file://$(find mobile_manipulator_body)/meshes/cam.stl"
          scale="0.001 0.001 0.001" />
      </geometry>
      <!-- <material name="dark" /> -->
      <color rgba="1 1 1 1" />
    </visual>
  </link>

  <joint name="camera_optical_joint" type="fixed">  
    <parent link="camera_link"/>
    <child link="camera_link_optical"/>
    <origin xyz="0 0 0" rpy="${-pi/2} 0 ${-pi/2}"/>
  </joint>

  <link name="camera_link_optical"></link>

   <gazebo reference="camera_link">
      <material>Gazebo/Red</material>
      <sensor name="camera" type="camera">
        <pose> 0 0 0 0 0 0 </pose>
        <visualize>true</visualize>
        <update_rate>10</update_rate>
        <camera>
          <horizontal_fov>1.089</horizontal_fov>
          <image>
            <format>R8G8B8</format>
            <width>640</width>
            <height>480</height>
          </image>
          <clip>
            <near>0.05</near>
            <far>8.0</far>
          </clip>
        </camera>
        <plugin name="camera_controller" filename="libgazebo_ros_camera.so">
            <frame_name>camera_link_optical</frame_name>
        </plugin>
      </sensor>
   </gazebo>
            <!--  -->

  <joint name="front_left_wheel_joint" type="continuous">
    <axis xyz="0 1 0" />
    <parent link="base_link" />
    <child link="front_left_wheel" />
    <origin rpy="0 0 0" xyz="0.220 0.250 0" />
  </joint>


  <joint name="front_right_wheel_joint" type="continuous">
    <axis xyz="0 1 0" />
    <parent link="base_link" />
    <child link="front_right_wheel" />
    <origin rpy="0 0 0" xyz="0.220 -0.250 0" />
  </joint>

  <joint name="rear_left_wheel_joint" type="continuous">
    <axis xyz="0 1 0" />
    <parent link="base_link" />
    <child link="rear_left_wheel" />
    <origin rpy="0 0 0" xyz="-0.220 0.250 0" />
  </joint>

  <joint name="rear_right_wheel_joint" type="continuous">
    <axis xyz="0 1 0" />
    <parent link="base_link" />
    <child link="rear_right_wheel" />
    <origin rpy="0 0 0" xyz="-0.220 -0.250 0" />
  </joint>

  <gazebo>
    <plugin name="rear_wheel" filename="libgazebo_ros_diff_drive.so">
      <!-- Wheel Information -->
      <left_joint>rear_left_wheel_joint</left_joint>
      <right_joint>rear_right_wheel_joint</right_joint>
      <wheel_separation>0.5</wheel_separation>
      <wheel_diameter>0.2</wheel_diameter>

      <!-- Limits -->
      <max_wheel_torque>200</max_wheel_torque>
      <max_wheel_acceleration>10.0</max_wheel_acceleration>

      <!-- Output -->
      <odometry_frame>odom</odometry_frame>
      <robot_base_frame>base_link</robot_base_frame>

      <publish_odom>true</publish_odom>
      <publish_odom_tf>true</publish_odom_tf>
      <publish_wheel_tf>true</publish_wheel_tf>
    </plugin>
  </gazebo>

  <gazebo>
    <plugin name="front_wheel" filename="libgazebo_ros_diff_drive.so">
      <left_joint>front_left_wheel_joint</left_joint>
      <right_joint>front_right_wheel_joint</right_joint>
      <wheel_separation>0.5</wheel_separation>
      <wheel_diameter>0.2</wheel_diameter>

      <max_wheel_torque>200</max_wheel_torque>
      <max_wheel_acceleration>10.0</max_wheel_acceleration>

      <odometry_frame>odom</odometry_frame>
      <robot_base_frame>base_link</robot_base_frame>

      <publish_odom>true</publish_odom>
      <publish_odom_tf>true</publish_odom_tf>
      <publish_wheel_tf>true</publish_wheel_tf>
    </plugin>
  </gazebo>

  <gazebo reference="front_left_wheel">
    <mu1 value="1.0" />
    <mu2 value="1.0" />
    <kp value="10000000.0" />
    <kd value="1.0" />
    <fdir1 value="1 0 0" />
  </gazebo>

  <gazebo reference="front_right_wheel">
    <mu1 value="1.0" />
    <mu2 value="1.0" />
    <kp value="10000000.0" />
    <kd value="1.0" />
    <fdir1 value="1 0 0" />
  </gazebo>

  <gazebo reference="rear_left_wheel">
    <mu1 value="1.0" />
    <mu2 value="1.0" />
    <kp value="10000000.0" />
    <kd value="1.0" />
    <fdir1 value="1 0 0" />
  </gazebo>

  <gazebo reference="rear_left_wheel">
    <mu1 value="1.0" />
    <mu2 value="1.0" />
    <kp value="10000000.0" />
    <kd value="1.0" />
    <fdir1 value="1 0 0" />
  </gazebo>

  <transmission
    name="front_left_wheel_trans" type="SimpleTransmission">
    <type>transmission_interface/SimpleTransmission</type>
    <actuator name="front_left_wheel_motor">
      <hardwareInterface>hardware_interface/VelocityJointInterface</hardwareInterface>
      <mechanicalReduction>1</mechanicalReduction>
    </actuator>
    <joint name="front_left_wheel_joint">
      <hardwareInterface>hardware_interface/VelocityJointInterface</hardwareInterface>
    </joint>
  </transmission>

  <transmission
    name="front_right_wheel_trans" type="SimpleTransmission">
    <type>transmission_interface/SimpleTransmission</type>
    <actuator name="front_right_wheel_motor">
      <hardwareInterface>hardware_interface/VelocityJointInterface</hardwareInterface>
      <mechanicalReduction>1</mechanicalReduction>
    </actuator>
    <joint name="front_right_wheel_joint">
      <hardwareInterface>hardware_interface/VelocityJointInterface</hardwareInterface>
    </joint>
  </transmission>

  <transmission
    name="rear_left_wheel_trans" type="SimpleTransmission">
    <type>transmission_interface/SimpleTransmission</type>
    <actuator name="rear_left_wheel_motor">
      <hardwareInterface>hardware_interface/VelocityJointInterface</hardwareInterface>
      <mechanicalReduction>1</mechanicalReduction>
    </actuator>
    <joint name="rear_left_wheel_joint">
      <hardwareInterface>hardware_interface/VelocityJointInterface</hardwareInterface>
    </joint>
  </transmission>

  <transmission
    name="rear_right_wheel_trans" type="SimpleTransmission">
    <type>transmission_interface/SimpleTransmission</type>
    <actuator name="rear_right_wheel_motor">
      <hardwareInterface>hardware_interface/VelocityJointInterface</hardwareInterface>
      <mechanicalReduction>1</mechanicalReduction>
    </actuator>
    <joint name="rear_right_wheel_joint">
      <hardwareInterface>hardware_interface/VelocityJointInterface</hardwareInterface>
    </joint>
  </transmission>
</robot>