<sdf version='1.7'>
  <world name='default'>
    <model name='ground_plane'>
      <static>1</static>
      <link name='link'>
        <collision name='collision'>
          <geometry>
            <plane>
              <normal>0 0 1</normal>
              <size>100 100</size>
            </plane>
          </geometry>
          <surface>
            <contact>
              <collide_bitmask>65535</collide_bitmask>
              <ode/>
            </contact>
            <friction>
              <ode>
                <mu>100</mu>
                <mu2>50</mu2>
              </ode>
              <torsional>
                <ode/>
              </torsional>
            </friction>
            <bounce/>
          </surface>
          <max_contacts>10</max_contacts>
        </collision>
        <visual name='visual'>
          <cast_shadows>0</cast_shadows>
          <geometry>
            <plane>
              <normal>0 0 1</normal>
              <size>100 100</size>
            </plane>
          </geometry>
          <material>
            <script>
              <uri>file://media/materials/scripts/gazebo.material</uri>
              <name>Gazebo/Grey</name>
            </script>
          </material>
        </visual>
        <self_collide>0</self_collide>
        <enable_wind>0</enable_wind>
        <kinematic>0</kinematic>
      </link>
    </model>
    <light name='sun' type='directional'>
      <cast_shadows>1</cast_shadows>
      <pose>0 0 10 0 -0 0</pose>
      <diffuse>0.8 0.8 0.8 1</diffuse>
      <specular>0.2 0.2 0.2 1</specular>
      <attenuation>
        <range>1000</range>
        <constant>0.9</constant>
        <linear>0.01</linear>
        <quadratic>0.001</quadratic>
      </attenuation>
      <direction>-0.5 0.1 -0.9</direction>
      <spot>
        <inner_angle>0</inner_angle>
        <outer_angle>0</outer_angle>
        <falloff>0</falloff>
      </spot>
    </light>
    <scene>
      <shadows>0</shadows>
      <ambient>0.4 0.4 0.4 1</ambient>
      <background>0.7 0.7 0.7 1</background>
    </scene>
    <plugin name='gazebo_ros_state' filename='libgazebo_ros_state.so'>
      <ros>
        <namespace>/ros2_grasp</namespace>
        <argument>model_states:=model_states</argument>
        <argument>link_states:=link_states</argument>
      </ros>
      <update_rate>1.0</update_rate>
    </plugin>
    <plugin name='gazebo_ros_properties' filename='libgazebo_ros_properties.so'>
      <ros>
        <namespace>/ros2_grasp</namespace>
      </ros>
    </plugin>
    <gravity>0 0 -9.8</gravity>
    <magnetic_field>6e-06 2.3e-05 -4.2e-05</magnetic_field>
    <atmosphere type='adiabatic'/>
    <physics type='ode'>
      <max_step_size>0.001</max_step_size>
      <real_time_factor>1</real_time_factor>
      <real_time_update_rate>1000</real_time_update_rate>
    </physics>
    <audio>
      <device>default</device>
    </audio>
    <wind/>
    <spherical_coordinates>
      <surface_model>EARTH_WGS84</surface_model>
      <latitude_deg>0</latitude_deg>
      <longitude_deg>0</longitude_deg>
      <elevation>0</elevation>
      <heading_deg>0</heading_deg>
    </spherical_coordinates>
    <model name='irb120'>
      <link name='base_link'>
        <inertial>
          <pose>0.002585 1e-06 0.055766 0 -0 0</pose>
          <mass>506.329</mass>
          <inertia>
            <ixx>8.01151</ixx>
            <ixy>-5.85698e-05</ixy>
            <ixz>0.129946</ixz>
            <iyy>16.8034</iyy>
            <iyz>-0.000105552</iyz>
            <izz>21.3045</izz>
          </inertia>
        </inertial>
        <collision name='base_link_fixed_joint_lump__base_footprint_collision'>
          <pose>0 0 0 1.5708 -0 3.14</pose>
          <geometry>
            <mesh>
              <scale>1 1 1</scale>
              <uri>file:///home/aarjan/Documents/syllabus/8thsem/robotics/mobile_robot_manipulator/install/mobile_manipulator_body/share/mobile_manipulator_body/meshes/robot_base.stl</uri>
            </mesh>
          </geometry>
          <max_contacts>10</max_contacts>
          <surface>
            <contact>
              <ode/>
            </contact>
            <bounce/>
            <friction>
              <torsional>
                <ode/>
              </torsional>
              <ode/>
            </friction>
          </surface>
        </collision>
        <collision name='base_link_arm_collision_1'>
          <pose>0 0 0.172 0 -0 0</pose>
          <geometry>
            <mesh>
              <scale>1 1 1</scale>
              <uri>file:///home/aarjan/Documents/syllabus/8thsem/robotics/mobile_robot_manipulator/install/irb120_ros2_gazebo/share/irb120_ros2_gazebo/meshes/collision/base_link.stl</uri>
            </mesh>
          </geometry>
          <surface>
            <contact>
              <ode/>
            </contact>
            <friction>
              <ode/>
              <torsional>
                <ode/>
              </torsional>
            </friction>
            <bounce/>
          </surface>
          <max_contacts>10</max_contacts>
        </collision>
        <collision name='base_link_fixed_joint_lump__base_scan_collision_2'>
          <pose>0.215 0 0.1655 0 -0 0</pose>
          <geometry>
            <cylinder>
              <length>0.0315</length>
              <radius>0.055</radius>
            </cylinder>
          </geometry>
          <surface>
            <contact>
              <ode/>
            </contact>
            <friction>
              <ode/>
              <torsional>
                <ode/>
              </torsional>
            </friction>
            <bounce/>
          </surface>
          <max_contacts>10</max_contacts>
        </collision>
        <visual name='base_link_fixed_joint_lump__base_footprint_visual'>
          <pose>0 0 0 1.5708 -0 3.14</pose>
          <geometry>
            <mesh>
              <scale>1 1 1</scale>
              <uri>file:///home/aarjan/Documents/syllabus/8thsem/robotics/mobile_robot_manipulator/install/mobile_manipulator_body/share/mobile_manipulator_body/meshes/robot_base.stl</uri>
            </mesh>
          </geometry>
        </visual>
        <visual name='base_link_arm_visual_1'>
          <pose>0 0 0.172 0 -0 0</pose>
          <geometry>
            <mesh>
              <scale>1 1 1</scale>
              <uri>file:///home/aarjan/Documents/syllabus/8thsem/robotics/mobile_robot_manipulator/install/irb120_ros2_gazebo/share/irb120_ros2_gazebo/meshes/visual/base_link.dae</uri>
            </mesh>
          </geometry>
        </visual>
        <visual name='base_link_fixed_joint_lump__base_scan_visual_2'>
          <pose>0.2 0 0.172 0 -0 0</pose>
          <geometry>
            <mesh>
              <scale>0.001 0.001 0.001</scale>
              <uri>file:///home/aarjan/Documents/syllabus/8thsem/robotics/mobile_robot_manipulator/install/mobile_manipulator_body/share/mobile_manipulator_body/meshes/lds.dae</uri>
            </mesh>
          </geometry>
          <material>
            <script>
              <name>Gazebo/Red</name>
              <uri>file://media/materials/scripts/gazebo.material</uri>
            </script>
          </material>
        </visual>
        <self_collide>0</self_collide>
        <sensor name='laser' type='ray'>
          <always_on>1</always_on>
          <visualize>1</visualize>
          <update_rate>5</update_rate>
          <ray>
            <scan>
              <horizontal>
                <samples>360</samples>
                <min_angle>0</min_angle>
                <max_angle>6.28</max_angle>
                <resolution>1</resolution>
              </horizontal>
              <vertical>
                <samples>1</samples>
                <min_angle>0</min_angle>
                <max_angle>0</max_angle>
              </vertical>
            </scan>
            <range>
              <min>0.12</min>
              <max>3.5</max>
            </range>
            <noise>
              <type>gaussian</type>
              <mean>0</mean>
              <stddev>0.01</stddev>
            </noise>
          </ray>
          <plugin name='laser_controller' filename='libgazebo_ros_ray_sensor.so'>
            <ros>
              <remapping>~/out:=scan</remapping>
            </ros>
            <output_type>sensor_msgs/LaserScan</output_type>
            <frame_name>base_scan</frame_name>
          </plugin>
          <pose>0.2 0 0.172 0 -0 0</pose>
        </sensor>
        <enable_wind>0</enable_wind>
        <kinematic>0</kinematic>
      </link>
      <joint name='joint_1' type='revolute'>
        <pose relative_to='base_link'>0 0 0.172 0 -0 0</pose>
        <parent>base_link</parent>
        <child>link_1</child>
        <axis>
          <xyz>0 0 1</xyz>
          <limit>
            <lower>-2.87979</lower>
            <upper>2.87979</upper>
            <effort>0</effort>
            <velocity>4.36332</velocity>
          </limit>
          <dynamics>
            <damping>50</damping>
            <friction>1</friction>
            <spring_reference>0</spring_reference>
            <spring_stiffness>0</spring_stiffness>
          </dynamics>
        </axis>
      </joint>
      <link name='link_1'>
        <pose relative_to='joint_1'>0 0 0 0 -0 0</pose>
        <inertial>
          <pose>9.8e-05 -0.00012 0.23841 0 -0 0</pose>
          <mass>3.067</mass>
          <inertia>
            <ixx>0.0142175</ixx>
            <ixy>-1.28579e-05</ixy>
            <ixz>-2.31364e-05</ixz>
            <iyy>0.0144041</iyy>
            <iyz>1.93404e-05</iyz>
            <izz>0.0104533</izz>
          </inertia>
        </inertial>
        <collision name='link_1_collision'>
          <pose>0 0 0 0 -0 0</pose>
          <geometry>
            <mesh>
              <scale>1 1 1</scale>
              <uri>file:///home/aarjan/Documents/syllabus/8thsem/robotics/mobile_robot_manipulator/install/irb120_ros2_gazebo/share/irb120_ros2_gazebo/meshes/collision/link_1.stl</uri>
            </mesh>
          </geometry>
          <surface>
            <contact>
              <ode/>
            </contact>
            <friction>
              <ode/>
              <torsional>
                <ode/>
              </torsional>
            </friction>
            <bounce/>
          </surface>
          <max_contacts>10</max_contacts>
        </collision>
        <visual name='link_1_visual'>
          <pose>0 0 0 0 -0 0</pose>
          <geometry>
            <mesh>
              <scale>1 1 1</scale>
              <uri>file:///home/aarjan/Documents/syllabus/8thsem/robotics/mobile_robot_manipulator/install/irb120_ros2_gazebo/share/irb120_ros2_gazebo/meshes/visual/link_1.dae</uri>
            </mesh>
          </geometry>
        </visual>
        <self_collide>0</self_collide>
        <enable_wind>0</enable_wind>
        <kinematic>0</kinematic>
      </link>
      <joint name='joint_2' type='revolute'>
        <pose relative_to='link_1'>0 0 0.29 0 -0 0</pose>
        <parent>link_1</parent>
        <child>link_2</child>
        <axis>
          <xyz>0 1 0</xyz>
          <limit>
            <lower>-1.91986</lower>
            <upper>1.91986</upper>
            <effort>0</effort>
            <velocity>4.36332</velocity>
          </limit>
          <dynamics>
            <damping>50</damping>
            <friction>1</friction>
            <spring_reference>0</spring_reference>
            <spring_stiffness>0</spring_stiffness>
          </dynamics>
        </axis>
      </joint>
      <link name='link_2'>
        <pose relative_to='joint_2'>0 0 0 0 -0 0</pose>
        <inertial>
          <pose>0.00078 -0.00212 0.10124 0 -0 0</pose>
          <mass>3.909</mass>
          <inertia>
            <ixx>0.0603111</ixx>
            <ixy>9.83431e-06</ixy>
            <ixz>5.72407e-05</ixz>
            <iyy>0.041569</iyy>
            <iyz>-0.00050497</iyz>
            <izz>0.0259548</izz>
          </inertia>
        </inertial>
        <collision name='link_2_collision'>
          <pose>0 0 0 0 -0 0</pose>
          <geometry>
            <mesh>
              <scale>1 1 1</scale>
              <uri>file:///home/aarjan/Documents/syllabus/8thsem/robotics/mobile_robot_manipulator/install/irb120_ros2_gazebo/share/irb120_ros2_gazebo/meshes/collision/link_2.stl</uri>
            </mesh>
          </geometry>
          <surface>
            <contact>
              <ode/>
            </contact>
            <friction>
              <ode/>
              <torsional>
                <ode/>
              </torsional>
            </friction>
            <bounce/>
          </surface>
          <max_contacts>10</max_contacts>
        </collision>
        <visual name='link_2_visual'>
          <pose>0 0 0 0 -0 0</pose>
          <geometry>
            <mesh>
              <scale>1 1 1</scale>
              <uri>file:///home/aarjan/Documents/syllabus/8thsem/robotics/mobile_robot_manipulator/install/irb120_ros2_gazebo/share/irb120_ros2_gazebo/meshes/visual/link_2.dae</uri>
            </mesh>
          </geometry>
        </visual>
        <self_collide>0</self_collide>
        <enable_wind>0</enable_wind>
        <kinematic>0</kinematic>
      </link>
      <joint name='joint_3' type='revolute'>
        <pose relative_to='link_2'>0 0 0.27 0 -0 0</pose>
        <parent>link_2</parent>
        <child>link_3</child>
        <axis>
          <xyz>0 1 0</xyz>
          <limit>
            <lower>-1.91986</lower>
            <upper>1.22173</upper>
            <effort>0</effort>
            <velocity>4.36332</velocity>
          </limit>
          <dynamics>
            <damping>10</damping>
            <friction>1</friction>
            <spring_reference>0</spring_reference>
            <spring_stiffness>0</spring_stiffness>
          </dynamics>
        </axis>
      </joint>
      <link name='link_3'>
        <pose relative_to='joint_3'>0 0 0 0 -0 0</pose>
        <inertial>
          <pose>0.02281 0.00106 0.05791 0 -0 0</pose>
          <mass>2.944</mass>
          <inertia>
            <ixx>0.00835606</ixx>
            <ixy>-8.01545e-05</ixy>
            <ixz>0.00142884</ixz>
            <iyy>0.016713</iyy>
            <iyz>-0.000182227</iyz>
            <izz>0.0126984</izz>
          </inertia>
        </inertial>
        <collision name='link_3_collision'>
          <pose>0 0 0 0 -0 0</pose>
          <geometry>
            <mesh>
              <scale>1 1 1</scale>
              <uri>file:///home/aarjan/Documents/syllabus/8thsem/robotics/mobile_robot_manipulator/install/irb120_ros2_gazebo/share/irb120_ros2_gazebo/meshes/collision/link_3.stl</uri>
            </mesh>
          </geometry>
          <surface>
            <contact>
              <ode/>
            </contact>
            <friction>
              <ode/>
              <torsional>
                <ode/>
              </torsional>
            </friction>
            <bounce/>
          </surface>
          <max_contacts>10</max_contacts>
        </collision>
        <visual name='link_3_visual'>
          <pose>0 0 0 0 -0 0</pose>
          <geometry>
            <mesh>
              <scale>1 1 1</scale>
              <uri>file:///home/aarjan/Documents/syllabus/8thsem/robotics/mobile_robot_manipulator/install/irb120_ros2_gazebo/share/irb120_ros2_gazebo/meshes/visual/link_3.dae</uri>
            </mesh>
          </geometry>
        </visual>
        <self_collide>0</self_collide>
        <enable_wind>0</enable_wind>
        <kinematic>0</kinematic>
      </link>
      <joint name='joint_4' type='revolute'>
        <pose relative_to='link_3'>0 0 0.07 0 -0 0</pose>
        <parent>link_3</parent>
        <child>link_4</child>
        <axis>
          <xyz>1 0 0</xyz>
          <limit>
            <lower>-2.79253</lower>
            <upper>2.79253</upper>
            <effort>0</effort>
            <velocity>5.58505</velocity>
          </limit>
          <dynamics>
            <damping>5</damping>
            <friction>1</friction>
            <spring_reference>0</spring_reference>
            <spring_stiffness>0</spring_stiffness>
          </dynamics>
        </axis>
      </joint>
      <link name='link_4'>
        <pose relative_to='joint_4'>0 0 0 0 -0 0</pose>
        <inertial>
          <pose>0.2247 0.00015 0.00041 0 -0 0</pose>
          <mass>1.328</mass>
          <inertia>
            <ixx>0.00284661</ixx>
            <ixy>-2.12765e-05</ixy>
            <ixz>-1.6435e-05</ixz>
            <iyy>0.00401346</iyy>
            <iyz>1.31336e-05</iyz>
            <izz>0.0052535</izz>
          </inertia>
        </inertial>
        <collision name='link_4_collision'>
          <pose>0 0 0 0 -0 0</pose>
          <geometry>
            <mesh>
              <scale>1 1 1</scale>
              <uri>file:///home/aarjan/Documents/syllabus/8thsem/robotics/mobile_robot_manipulator/install/irb120_ros2_gazebo/share/irb120_ros2_gazebo/meshes/collision/link_4.stl</uri>
            </mesh>
          </geometry>
          <surface>
            <contact>
              <ode/>
            </contact>
            <friction>
              <ode/>
              <torsional>
                <ode/>
              </torsional>
            </friction>
            <bounce/>
          </surface>
          <max_contacts>10</max_contacts>
        </collision>
        <visual name='link_4_visual'>
          <pose>0 0 0 0 -0 0</pose>
          <geometry>
            <mesh>
              <scale>1 1 1</scale>
              <uri>file:///home/aarjan/Documents/syllabus/8thsem/robotics/mobile_robot_manipulator/install/irb120_ros2_gazebo/share/irb120_ros2_gazebo/meshes/visual/link_4.dae</uri>
            </mesh>
          </geometry>
        </visual>
        <self_collide>0</self_collide>
        <enable_wind>0</enable_wind>
        <kinematic>0</kinematic>
      </link>
      <joint name='joint_5' type='revolute'>
        <pose relative_to='link_4'>0.302 0 0 0 -0 0</pose>
        <parent>link_4</parent>
        <child>link_5</child>
        <axis>
          <xyz>0 1 0</xyz>
          <limit>
            <lower>-2.0944</lower>
            <upper>2.0944</upper>
            <effort>0</effort>
            <velocity>5.58505</velocity>
          </limit>
          <dynamics>
            <damping>2</damping>
            <friction>1</friction>
            <spring_reference>0</spring_reference>
            <spring_stiffness>0</spring_stiffness>
          </dynamics>
        </axis>
      </joint>
      <link name='link_5'>
        <pose relative_to='joint_5'>0 0 0 0 -0 0</pose>
        <inertial>
          <pose>-0.00109 3.7e-05 6.2e-05 0 -0 0</pose>
          <mass>0.546</mass>
          <inertia>
            <ixx>0.000404891</ixx>
            <ixy>1.61943e-06</ixy>
            <ixz>8.46805e-07</ixz>
            <iyy>0.000892825</iyy>
            <iyz>-1.51792e-08</iyz>
            <izz>0.000815468</izz>
          </inertia>
        </inertial>
        <collision name='link_5_collision'>
          <pose>0 0 0 0 -0 0</pose>
          <geometry>
            <mesh>
              <scale>1 1 1</scale>
              <uri>file:///home/aarjan/Documents/syllabus/8thsem/robotics/mobile_robot_manipulator/install/irb120_ros2_gazebo/share/irb120_ros2_gazebo/meshes/collision/link_5.stl</uri>
            </mesh>
          </geometry>
          <surface>
            <contact>
              <ode/>
            </contact>
            <friction>
              <ode/>
              <torsional>
                <ode/>
              </torsional>
            </friction>
            <bounce/>
          </surface>
          <max_contacts>10</max_contacts>
        </collision>
        <visual name='link_5_visual'>
          <pose>0 0 0 0 -0 0</pose>
          <geometry>
            <mesh>
              <scale>1 1 1</scale>
              <uri>file:///home/aarjan/Documents/syllabus/8thsem/robotics/mobile_robot_manipulator/install/irb120_ros2_gazebo/share/irb120_ros2_gazebo/meshes/visual/link_5.dae</uri>
            </mesh>
          </geometry>
        </visual>
        <self_collide>0</self_collide>
        <enable_wind>0</enable_wind>
        <kinematic>0</kinematic>
      </link>
      <joint name='joint_6' type='revolute'>
        <pose relative_to='link_5'>0.072 0 0 0 -0 0</pose>
        <parent>link_5</parent>
        <child>link_6</child>
        <axis>
          <xyz>1 0 0</xyz>
          <limit>
            <lower>-6.98132</lower>
            <upper>6.98132</upper>
            <effort>0</effort>
            <velocity>7.33038</velocity>
          </limit>
          <dynamics>
            <damping>1</damping>
            <friction>1</friction>
            <spring_reference>0</spring_reference>
            <spring_stiffness>0</spring_stiffness>
          </dynamics>
        </axis>
      </joint>
      <link name='link_6'>
        <pose relative_to='joint_6'>0 0 0 0 -0 0</pose>
        <inertial>
          <pose>-0.006006 -0.000507 0.001239 0 -0 0</pose>
          <mass>0.143</mass>
          <inertia>
            <ixx>0.00300653</ixx>
            <ixy>1.32865e-06</ixy>
            <ixz>-4.87384e-06</ixz>
            <iyy>0.00301005</iyy>
            <iyz>1.65725e-06</iyz>
            <izz>0.00300443</izz>
          </inertia>
        </inertial>
        <collision name='link_6_collision'>
          <pose>0 0 0 0 -0 0</pose>
          <geometry>
            <mesh>
              <scale>1 1 1</scale>
              <uri>file:///home/aarjan/Documents/syllabus/8thsem/robotics/mobile_robot_manipulator/install/irb120_ros2_gazebo/share/irb120_ros2_gazebo/meshes/collision/link_6.stl</uri>
            </mesh>
          </geometry>
          <surface>
            <contact>
              <ode/>
            </contact>
            <friction>
              <ode/>
              <torsional>
                <ode/>
              </torsional>
            </friction>
            <bounce/>
          </surface>
          <max_contacts>10</max_contacts>
        </collision>
        <collision name='link_6_fixed_joint_lump__schunk_coupler_collision_1'>
          <pose>0.001 0 0 1.5708 0.785398 1.5708</pose>
          <geometry>
            <mesh>
              <scale>1 1 1</scale>
              <uri>file:///home/aarjan/Documents/syllabus/8thsem/robotics/mobile_robot_manipulator/install/irb120_ros2_gazebo/share/irb120_ros2_gazebo/meshes/egp64/egp64_Adapter.dae</uri>
            </mesh>
          </geometry>
          <surface>
            <contact>
              <ode/>
            </contact>
            <friction>
              <ode>
                <mu>0.9</mu>
                <mu2>0.9</mu2>
              </ode>
              <torsional>
                <ode/>
              </torsional>
            </friction>
            <bounce/>
          </surface>
          <max_contacts>10</max_contacts>
        </collision>
        <collision name='link_6_fixed_joint_lump__egp64_gripper_base_link_collision_2'>
          <pose>0.02147 -0.00985 0.035476 1.5708 0.785398 1.5708</pose>
          <geometry>
            <mesh>
              <scale>1 1 1</scale>
              <uri>file:///home/aarjan/Documents/syllabus/8thsem/robotics/mobile_robot_manipulator/install/irb120_ros2_gazebo/share/irb120_ros2_gazebo/meshes/egp64/egp64_BaseNoAdapter.dae</uri>
            </mesh>
          </geometry>
          <surface>
            <contact>
              <ode/>
            </contact>
            <friction>
              <ode/>
              <torsional>
                <ode/>
              </torsional>
            </friction>
            <bounce/>
          </surface>
          <max_contacts>10</max_contacts>
        </collision>
        <visual name='link_6_visual'>
          <pose>0 0 0 0 -0 0</pose>
          <geometry>
            <mesh>
              <scale>1 1 1</scale>
              <uri>file:///home/aarjan/Documents/syllabus/8thsem/robotics/mobile_robot_manipulator/install/irb120_ros2_gazebo/share/irb120_ros2_gazebo/meshes/visual/link_6.dae</uri>
            </mesh>
          </geometry>
        </visual>
        <visual name='link_6_fixed_joint_lump__schunk_coupler_visual_1'>
          <pose>0.001 0 0 1.5708 0.785398 1.5708</pose>
          <geometry>
            <mesh>
              <scale>1 1 1</scale>
              <uri>file:///home/aarjan/Documents/syllabus/8thsem/robotics/mobile_robot_manipulator/install/irb120_ros2_gazebo/share/irb120_ros2_gazebo/meshes/egp64/egp64_Adapter.dae</uri>
            </mesh>
          </geometry>
          <material>
            <script>
              <name>Gazebo/Black</name>
              <uri>file://media/materials/scripts/gazebo.material</uri>
            </script>
          </material>
        </visual>
        <visual name='link_6_fixed_joint_lump__egp64_gripper_base_link_visual_2'>
          <pose>0.02147 -0.00985 0.035476 1.5708 0.785398 1.5708</pose>
          <geometry>
            <mesh>
              <scale>1 1 1</scale>
              <uri>file:///home/aarjan/Documents/syllabus/8thsem/robotics/mobile_robot_manipulator/install/irb120_ros2_gazebo/share/irb120_ros2_gazebo/meshes/egp64/egp64_BaseNoAdapter.dae</uri>
            </mesh>
          </geometry>
        </visual>
        <self_collide>0</self_collide>
        <enable_wind>0</enable_wind>
        <kinematic>0</kinematic>
      </link>
      <joint name='EE_egp64_joint' type='prismatic'>
        <pose relative_to='link_6'>0.17147 0.000757 -0.000587 1.5708 0.785398 1.5708</pose>
        <parent>link_6</parent>
        <child>EE_egp64</child>
        <axis>
          <xyz>1 0 0</xyz>
          <limit>
            <lower>0</lower>
            <upper>0</upper>
            <effort>10000</effort>
            <velocity>0</velocity>
          </limit>
          <dynamics>
            <damping>1</damping>
            <friction>1</friction>
            <spring_reference>0</spring_reference>
            <spring_stiffness>0</spring_stiffness>
          </dynamics>
        </axis>
      </joint>
      <link name='EE_egp64'>
        <pose relative_to='EE_egp64_joint'>0 0 0 0 -0 0</pose>
        <inertial>
          <pose>0 0 0 0 -0 0</pose>
          <mass>1e-05</mass>
          <inertia>
            <ixx>0.001</ixx>
            <ixy>0</ixy>
            <ixz>0</ixz>
            <iyy>0.001</iyy>
            <iyz>0</iyz>
            <izz>0.001</izz>
          </inertia>
        </inertial>
        <collision name='EE_egp64_collision'>
          <pose>0 0 0 0 -0 0</pose>
          <geometry>
            <box>
              <size>0.001 0.001 0.001</size>
            </box>
          </geometry>
          <max_contacts>10</max_contacts>
          <surface>
            <contact>
              <ode/>
            </contact>
            <bounce/>
            <friction>
              <torsional>
                <ode/>
              </torsional>
              <ode/>
            </friction>
          </surface>
        </collision>
        <visual name='EE_egp64_visual'>
          <pose>0 0 0 0 -0 0</pose>
          <geometry>
            <box>
              <size>0.001 0.001 0.001</size>
            </box>
          </geometry>
        </visual>
        <self_collide>0</self_collide>
        <enable_wind>0</enable_wind>
        <kinematic>0</kinematic>
      </link>
      <joint name='egp64_finger_left_joint' type='prismatic'>
        <pose relative_to='link_6'>0.02147 -0.004893 0.01946 1.5708 0.785398 1.5708</pose>
        <parent>link_6</parent>
        <child>egp64_finger_left_link</child>
        <axis>
          <xyz>-1 0 0</xyz>
          <limit>
            <lower>-0.001</lower>
            <upper>0.04</upper>
            <effort>100</effort>
            <velocity>0.2</velocity>
          </limit>
          <dynamics>
            <damping>1</damping>
            <friction>1</friction>
            <spring_reference>0</spring_reference>
            <spring_stiffness>0</spring_stiffness>
          </dynamics>
        </axis>
      </joint>
      <link name='egp64_finger_left_link'>
        <pose relative_to='egp64_finger_left_joint'>0 0 0 0 -0 0</pose>
        <inertial>
          <pose>0.03568 -0.005547 0.00062 0 -0 0</pose>
          <mass>0.003</mass>
          <inertia>
            <ixx>0.00200003</ixx>
            <ixy>-2.84394e-07</ixy>
            <ixz>-7.7562e-08</ixz>
            <iyy>0.00200261</iyy>
            <iyz>-8.4568e-09</iyz>
            <izz>0.00200264</izz>
          </inertia>
        </inertial>
        <collision name='egp64_finger_left_link_collision'>
          <pose>0 0 0 0 -0 0</pose>
          <geometry>
            <mesh>
              <scale>1 1 1</scale>
              <uri>file:///home/aarjan/Documents/syllabus/8thsem/robotics/mobile_robot_manipulator/install/irb120_ros2_gazebo/share/irb120_ros2_gazebo/meshes/egp64/egp64_LeftFingerBase.dae</uri>
            </mesh>
          </geometry>
          <surface>
            <contact>
              <ode/>
            </contact>
            <friction>
              <ode/>
              <torsional>
                <ode/>
              </torsional>
            </friction>
            <bounce/>
          </surface>
          <max_contacts>10</max_contacts>
        </collision>
        <collision name='egp64_finger_left_link_fixed_joint_lump__egp64_fingertip_left_link_collision_1'>
          <pose>0.03869 -0.0005 0.00093 0 -0 0</pose>
          <geometry>
            <mesh>
              <scale>1 1 1</scale>
              <uri>file:///home/aarjan/Documents/syllabus/8thsem/robotics/mobile_robot_manipulator/install/irb120_ros2_gazebo/share/irb120_ros2_gazebo/meshes/egp64/egp64_LeftFinger.dae</uri>
            </mesh>
          </geometry>
          <surface>
            <contact>
              <ode/>
            </contact>
            <friction>
              <ode/>
              <torsional>
                <ode/>
              </torsional>
            </friction>
            <bounce/>
          </surface>
          <max_contacts>10</max_contacts>
        </collision>
        <visual name='egp64_finger_left_link_visual'>
          <pose>0 0 0 0 -0 0</pose>
          <geometry>
            <mesh>
              <scale>1 1 1</scale>
              <uri>file:///home/aarjan/Documents/syllabus/8thsem/robotics/mobile_robot_manipulator/install/irb120_ros2_gazebo/share/irb120_ros2_gazebo/meshes/egp64/egp64_LeftFingerBase.dae</uri>
            </mesh>
          </geometry>
        </visual>
        <visual name='egp64_finger_left_link_fixed_joint_lump__egp64_fingertip_left_link_visual_1'>
          <pose>0.03869 -0.0005 0.00093 0 -0 0</pose>
          <geometry>
            <mesh>
              <scale>1 1 1</scale>
              <uri>file:///home/aarjan/Documents/syllabus/8thsem/robotics/mobile_robot_manipulator/install/irb120_ros2_gazebo/share/irb120_ros2_gazebo/meshes/egp64/egp64_LeftFinger.dae</uri>
            </mesh>
          </geometry>
        </visual>
        <self_collide>0</self_collide>
        <enable_wind>0</enable_wind>
        <kinematic>0</kinematic>
      </link>
      <joint name='egp64_finger_right_joint' type='prismatic'>
        <pose relative_to='link_6'>0.02147 -0.024926 0.042037 1.5708 0.785398 1.5708</pose>
        <parent>link_6</parent>
        <child>egp64_finger_right_link</child>
        <axis>
          <xyz>1 0 0</xyz>
          <limit>
            <lower>-0.001</lower>
            <upper>0.04</upper>
            <effort>100</effort>
            <velocity>0.2</velocity>
          </limit>
          <dynamics>
            <damping>1</damping>
            <friction>1</friction>
            <spring_reference>0</spring_reference>
            <spring_stiffness>0</spring_stiffness>
          </dynamics>
        </axis>
      </joint>
      <link name='egp64_finger_right_link'>
        <pose relative_to='egp64_finger_right_joint'>0 0 0 0 -0 0</pose>
        <inertial>
          <pose>-0.018273 -0.005327 0.00062 0 -0 0</pose>
          <mass>0.003</mass>
          <inertia>
            <ixx>0.00200001</ixx>
            <ixy>1.23691e-08</ixy>
            <ixz>1.10608e-08</ixz>
            <iyy>0.00200006</iyy>
            <iyz>-2.5792e-09</iyz>
            <izz>0.00200006</izz>
          </inertia>
        </inertial>
        <collision name='egp64_finger_right_link_collision'>
          <pose>0 0 0 0 -0 0</pose>
          <geometry>
            <mesh>
              <scale>1 1 1</scale>
              <uri>file:///home/aarjan/Documents/syllabus/8thsem/robotics/mobile_robot_manipulator/install/irb120_ros2_gazebo/share/irb120_ros2_gazebo/meshes/egp64/egp64_RightFingerBase.dae</uri>
            </mesh>
          </geometry>
          <surface>
            <contact>
              <ode/>
            </contact>
            <friction>
              <ode/>
              <torsional>
                <ode/>
              </torsional>
            </friction>
            <bounce/>
          </surface>
          <max_contacts>10</max_contacts>
        </collision>
        <collision name='egp64_finger_right_link_fixed_joint_lump__egp64_fingertip_right_link_collision_1'>
          <pose>-0.01211 -0.00197 0.00093 0 -0 0</pose>
          <geometry>
            <mesh>
              <scale>1 1 1</scale>
              <uri>file:///home/aarjan/Documents/syllabus/8thsem/robotics/mobile_robot_manipulator/install/irb120_ros2_gazebo/share/irb120_ros2_gazebo/meshes/egp64/egp64_RightFinger.dae</uri>
            </mesh>
          </geometry>
          <surface>
            <contact>
              <ode/>
            </contact>
            <friction>
              <ode/>
              <torsional>
                <ode/>
              </torsional>
            </friction>
            <bounce/>
          </surface>
          <max_contacts>10</max_contacts>
        </collision>
        <visual name='egp64_finger_right_link_visual'>
          <pose>0 0 0 0 -0 0</pose>
          <geometry>
            <mesh>
              <scale>1 1 1</scale>
              <uri>file:///home/aarjan/Documents/syllabus/8thsem/robotics/mobile_robot_manipulator/install/irb120_ros2_gazebo/share/irb120_ros2_gazebo/meshes/egp64/egp64_RightFingerBase.dae</uri>
            </mesh>
          </geometry>
        </visual>
        <visual name='egp64_finger_right_link_fixed_joint_lump__egp64_fingertip_right_link_visual_1'>
          <pose>-0.01211 -0.00197 0.00093 0 -0 0</pose>
          <geometry>
            <mesh>
              <scale>1 1 1</scale>
              <uri>file:///home/aarjan/Documents/syllabus/8thsem/robotics/mobile_robot_manipulator/install/irb120_ros2_gazebo/share/irb120_ros2_gazebo/meshes/egp64/egp64_RightFinger.dae</uri>
            </mesh>
          </geometry>
        </visual>
        <self_collide>0</self_collide>
        <enable_wind>0</enable_wind>
        <kinematic>0</kinematic>
      </link>
      <joint name='front_left_wheel_joint' type='revolute'>
        <pose relative_to='base_link'>0.22 0.25 0 0 -0 0</pose>
        <parent>base_link</parent>
        <child>front_left_wheel</child>
        <axis>
          <xyz>0 1 0</xyz>
          <limit>
            <lower>-1e+16</lower>
            <upper>1e+16</upper>
          </limit>
          <dynamics>
            <spring_reference>0</spring_reference>
            <spring_stiffness>0</spring_stiffness>
          </dynamics>
        </axis>
      </joint>
      <link name='front_left_wheel'>
        <pose relative_to='front_left_wheel_joint'>0 0 0 0 -0 0</pose>
        <inertial>
          <pose>-0 0.006809 -0 0 -0 0</pose>
          <mass>2.6578</mass>
          <inertia>
            <ixx>0.00856503</ixx>
            <ixy>1.50741e-19</ixy>
            <ixz>-4.7815e-19</ixz>
            <iyy>0.0136706</iyy>
            <iyz>-2.68136e-19</iyz>
            <izz>0.00856503</izz>
          </inertia>
        </inertial>
        <collision name='front_left_wheel_collision'>
          <pose>0 0 0 1.5708 -0 0</pose>
          <geometry>
            <mesh>
              <scale>1 1 1</scale>
              <uri>file:///home/aarjan/Documents/syllabus/8thsem/robotics/mobile_robot_manipulator/install/mobile_manipulator_body/share/mobile_manipulator_body/meshes/wheel.stl</uri>
            </mesh>
          </geometry>
          <surface>
            <contact>
              <ode>
                <kp>1e+07</kp>
                <kd>1</kd>
              </ode>
            </contact>
            <friction>
              <ode>
                <mu>1</mu>
                <mu2>1</mu2>
                <fdir1>1 0 0</fdir1>
              </ode>
              <torsional>
                <ode/>
              </torsional>
            </friction>
            <bounce/>
          </surface>
          <max_contacts>10</max_contacts>
        </collision>
        <visual name='front_left_wheel_visual'>
          <pose>0 0 0 1.5708 -0 0</pose>
          <geometry>
            <mesh>
              <scale>1 1 1</scale>
              <uri>file:///home/aarjan/Documents/syllabus/8thsem/robotics/mobile_robot_manipulator/install/mobile_manipulator_body/share/mobile_manipulator_body/meshes/wheel.stl</uri>
            </mesh>
          </geometry>
        </visual>
        <self_collide>0</self_collide>
        <enable_wind>0</enable_wind>
        <kinematic>0</kinematic>
      </link>
      <joint name='front_right_wheel_joint' type='revolute'>
        <pose relative_to='base_link'>0.22 -0.25 0 0 -0 0</pose>
        <parent>base_link</parent>
        <child>front_right_wheel</child>
        <axis>
          <xyz>0 1 0</xyz>
          <limit>
            <lower>-1e+16</lower>
            <upper>1e+16</upper>
          </limit>
          <dynamics>
            <spring_reference>0</spring_reference>
            <spring_stiffness>0</spring_stiffness>
          </dynamics>
        </axis>
      </joint>
      <link name='front_right_wheel'>
        <pose relative_to='front_right_wheel_joint'>0 0 0 0 -0 0</pose>
        <inertial>
          <pose>-0 0.006809 -0 0 -0 0</pose>
          <mass>2.6578</mass>
          <inertia>
            <ixx>0.00856503</ixx>
            <ixy>1.50741e-19</ixy>
            <ixz>-4.7815e-19</ixz>
            <iyy>0.0136706</iyy>
            <iyz>-2.68136e-19</iyz>
            <izz>0.00856503</izz>
          </inertia>
        </inertial>
        <collision name='front_right_wheel_collision'>
          <pose>0 0 0 1.5708 -0 0</pose>
          <geometry>
            <mesh>
              <scale>1 1 1</scale>
              <uri>file:///home/aarjan/Documents/syllabus/8thsem/robotics/mobile_robot_manipulator/install/mobile_manipulator_body/share/mobile_manipulator_body/meshes/wheel.stl</uri>
            </mesh>
          </geometry>
          <surface>
            <contact>
              <ode>
                <kp>1e+07</kp>
                <kd>1</kd>
              </ode>
            </contact>
            <friction>
              <ode>
                <mu>1</mu>
                <mu2>1</mu2>
                <fdir1>1 0 0</fdir1>
              </ode>
              <torsional>
                <ode/>
              </torsional>
            </friction>
            <bounce/>
          </surface>
          <max_contacts>10</max_contacts>
        </collision>
        <visual name='front_right_wheel_visual'>
          <pose>0 0 0 1.5708 -0 0</pose>
          <geometry>
            <mesh>
              <scale>1 1 1</scale>
              <uri>file:///home/aarjan/Documents/syllabus/8thsem/robotics/mobile_robot_manipulator/install/mobile_manipulator_body/share/mobile_manipulator_body/meshes/wheel.stl</uri>
            </mesh>
          </geometry>
        </visual>
        <self_collide>0</self_collide>
        <enable_wind>0</enable_wind>
        <kinematic>0</kinematic>
      </link>
      <joint name='rear_left_wheel_joint' type='revolute'>
        <pose relative_to='base_link'>-0.22 0.25 0 0 -0 0</pose>
        <parent>base_link</parent>
        <child>rear_left_wheel</child>
        <axis>
          <xyz>0 1 0</xyz>
          <limit>
            <lower>-1e+16</lower>
            <upper>1e+16</upper>
          </limit>
          <dynamics>
            <spring_reference>0</spring_reference>
            <spring_stiffness>0</spring_stiffness>
          </dynamics>
        </axis>
      </joint>
      <link name='rear_left_wheel'>
        <pose relative_to='rear_left_wheel_joint'>0 0 0 0 -0 0</pose>
        <inertial>
          <pose>-0 0.006809 -0 0 -0 0</pose>
          <mass>2.6578</mass>
          <inertia>
            <ixx>0.00856503</ixx>
            <ixy>1.50741e-19</ixy>
            <ixz>-4.7815e-19</ixz>
            <iyy>0.0136706</iyy>
            <iyz>-2.68136e-19</iyz>
            <izz>0.00856503</izz>
          </inertia>
        </inertial>
        <collision name='rear_left_wheel_collision'>
          <pose>0 0 0 1.5708 -0 0</pose>
          <geometry>
            <mesh>
              <scale>1 1 1</scale>
              <uri>file:///home/aarjan/Documents/syllabus/8thsem/robotics/mobile_robot_manipulator/install/mobile_manipulator_body/share/mobile_manipulator_body/meshes/wheel.stl</uri>
            </mesh>
          </geometry>
          <surface>
            <contact>
              <ode>
                <kp>1e+07</kp>
                <kd>1</kd>
              </ode>
            </contact>
            <friction>
              <ode>
                <mu>1</mu>
                <mu2>1</mu2>
                <fdir1>1 0 0</fdir1>
              </ode>
              <torsional>
                <ode/>
              </torsional>
            </friction>
            <bounce/>
          </surface>
          <max_contacts>10</max_contacts>
        </collision>
        <visual name='rear_left_wheel_visual'>
          <pose>0 0 0 1.5708 -0 0</pose>
          <geometry>
            <mesh>
              <scale>1 1 1</scale>
              <uri>file:///home/aarjan/Documents/syllabus/8thsem/robotics/mobile_robot_manipulator/install/mobile_manipulator_body/share/mobile_manipulator_body/meshes/wheel.stl</uri>
            </mesh>
          </geometry>
        </visual>
        <self_collide>0</self_collide>
        <enable_wind>0</enable_wind>
        <kinematic>0</kinematic>
      </link>
      <joint name='rear_right_wheel_joint' type='revolute'>
        <pose relative_to='base_link'>-0.22 -0.25 0 0 -0 0</pose>
        <parent>base_link</parent>
        <child>rear_right_wheel</child>
        <axis>
          <xyz>0 1 0</xyz>
          <limit>
            <lower>-1e+16</lower>
            <upper>1e+16</upper>
          </limit>
          <dynamics>
            <spring_reference>0</spring_reference>
            <spring_stiffness>0</spring_stiffness>
          </dynamics>
        </axis>
      </joint>
      <link name='rear_right_wheel'>
        <pose relative_to='rear_right_wheel_joint'>0 0 0 0 -0 0</pose>
        <inertial>
          <pose>-0 0.006809 -0 0 -0 0</pose>
          <mass>2.6578</mass>
          <inertia>
            <ixx>0.00856503</ixx>
            <ixy>1.50741e-19</ixy>
            <ixz>-4.7815e-19</ixz>
            <iyy>0.0136706</iyy>
            <iyz>-2.68136e-19</iyz>
            <izz>0.00856503</izz>
          </inertia>
        </inertial>
        <collision name='rear_right_wheel_collision'>
          <pose>0 0 0 1.5708 -0 0</pose>
          <geometry>
            <mesh>
              <scale>1 1 1</scale>
              <uri>file:///home/aarjan/Documents/syllabus/8thsem/robotics/mobile_robot_manipulator/install/mobile_manipulator_body/share/mobile_manipulator_body/meshes/wheel.stl</uri>
            </mesh>
          </geometry>
          <max_contacts>10</max_contacts>
          <surface>
            <contact>
              <ode/>
            </contact>
            <bounce/>
            <friction>
              <torsional>
                <ode/>
              </torsional>
              <ode/>
            </friction>
          </surface>
        </collision>
        <visual name='rear_right_wheel_visual'>
          <pose>0 0 0 1.5708 -0 0</pose>
          <geometry>
            <mesh>
              <scale>1 1 1</scale>
              <uri>file:///home/aarjan/Documents/syllabus/8thsem/robotics/mobile_robot_manipulator/install/mobile_manipulator_body/share/mobile_manipulator_body/meshes/wheel.stl</uri>
            </mesh>
          </geometry>
        </visual>
        <self_collide>0</self_collide>
        <enable_wind>0</enable_wind>
        <kinematic>0</kinematic>
      </link>
      <plugin name='gazebo_ros2_control' filename='libgazebo_ros2_control.so'>
        <robot_sim_type>gazebo_ros2_control/GazeboSystem</robot_sim_type>
        <parameters>/home/aarjan/Documents/syllabus/8thsem/robotics/mobile_robot_manipulator/install/irb120_ros2_gazebo/share/irb120_ros2_gazebo/config/irb120egp64_controller.yaml</parameters>
      </plugin>
      <plugin name='rear_wheel' filename='libgazebo_ros_diff_drive.so'>
        <left_joint>rear_left_wheel_joint</left_joint>
        <right_joint>rear_right_wheel_joint</right_joint>
        <wheel_separation>0.5</wheel_separation>
        <wheel_diameter>0.2</wheel_diameter>
        <max_wheel_torque>200</max_wheel_torque>
        <max_wheel_acceleration>10.0</max_wheel_acceleration>
        <odometry_frame>odom</odometry_frame>
        <robot_base_frame>base_link</robot_base_frame>
        <publish_odom>1</publish_odom>
        <publish_odom_tf>1</publish_odom_tf>
        <publish_wheel_tf>1</publish_wheel_tf>
      </plugin>
      <plugin name='front_wheel' filename='libgazebo_ros_diff_drive.so'>
        <left_joint>front_left_wheel_joint</left_joint>
        <right_joint>front_right_wheel_joint</right_joint>
        <wheel_separation>0.5</wheel_separation>
        <wheel_diameter>0.2</wheel_diameter>
        <max_wheel_torque>200</max_wheel_torque>
        <max_wheel_acceleration>10.0</max_wheel_acceleration>
        <odometry_frame>odom</odometry_frame>
        <robot_base_frame>base_link</robot_base_frame>
        <publish_odom>1</publish_odom>
        <publish_odom_tf>1</publish_odom_tf>
        <publish_wheel_tf>1</publish_wheel_tf>
      </plugin>
      <frame name='base_link-base' attached_to='base_link_arm'>
        <pose>0 0 0 0 -0 0</pose>
      </frame>
      <frame name='base' attached_to='base_link-base'/>
      <frame name='base_link_arm_joint' attached_to='base_footprint'>
        <pose>0 0 0.172 0 -0 0</pose>
      </frame>
      <frame name='base_link_arm' attached_to='base_link_arm_joint'/>
      <frame name='egp64_coupler' attached_to='schunk_coupler'>
        <pose>-0.03205 0.01812 0.02047 0 -0 0</pose>
      </frame>
      <frame name='egp64_gripper_base_link' attached_to='egp64_coupler'/>
      <frame name='egp64_fingertip_left_joint' attached_to='egp64_finger_left_link'>
        <pose>0.03869 -0.0005 0.00093 0 -0 0</pose>
      </frame>
      <frame name='egp64_fingertip_left_link' attached_to='egp64_fingertip_left_joint'/>
      <frame name='egp64_fingertip_right_joint' attached_to='egp64_finger_right_link'>
        <pose>-0.01211 -0.00197 0.00093 0 -0 0</pose>
      </frame>
      <frame name='egp64_fingertip_right_link' attached_to='egp64_fingertip_right_joint'/>
      <frame name='schunk_coupler_joint' attached_to='tool0'>
        <pose>0 0 0.001 0 -0 0.785398</pose>
      </frame>
      <frame name='schunk_coupler' attached_to='schunk_coupler_joint'/>
      <frame name='link_6-tool0' attached_to='flange'>
        <pose>0 0 0 3.14159 1.57079 3.14159</pose>
      </frame>
      <frame name='tool0' attached_to='link_6-tool0'/>
      <frame name='$joint_6-flange' attached_to='link_6'>
        <pose>0 0 0 0 -0 0</pose>
      </frame>
      <frame name='flange' attached_to='$joint_6-flange'/>
      <frame name='base_footprint_joint' attached_to='base_link'>
        <pose>0 0 0 0 -0 0</pose>
      </frame>
      <frame name='base_footprint' attached_to='base_footprint_joint'/>
      <frame name='imu_joint' attached_to='base_link'>
        <pose>-0.032 0 0.068 0 -0 0</pose>
      </frame>
      <frame name='imu_link' attached_to='imu_joint'/>
      <frame name='scan_joint' attached_to='base_link'>
        <pose>0.2 0 0.172 0 -0 0</pose>
      </frame>
      <frame name='base_scan' attached_to='scan_joint'/>
      <pose>0 0 0 0 -0 0</pose>
    </model>
    <model name='Fridge_Cabinet_33x15'>
      <link name='Wall_17'>
        <pose>0 0 0.01 0 -0 0</pose>
        <inertial>
          <mass>4.8627</mass>
          <inertia>
            <ixx>0.146</ixx>
            <iyy>0.4318</iyy>
            <izz>0.2861</izz>
            <ixy>0</ixy>
            <ixz>0</ixz>
            <iyz>0</iyz>
          </inertia>
        </inertial>
        <collision name='Wall_17_Collision'>
          <geometry>
            <box>
              <size>0.84 0.6 0.02</size>
            </box>
          </geometry>
          <max_contacts>10</max_contacts>
          <surface>
            <contact>
              <ode/>
            </contact>
            <bounce/>
            <friction>
              <torsional>
                <ode/>
              </torsional>
              <ode/>
            </friction>
          </surface>
        </collision>
        <visual name='Wall_17_Visual'>
          <geometry>
            <box>
              <size>0.84 0.6 0.02</size>
            </box>
          </geometry>
          <material>
            <script>
              <uri>file://media/materials/scripts/gazebo.material</uri>
              <name>Gazebo/Grey</name>
            </script>
            <ambient>1 0.764706 0.305882 1</ambient>
          </material>
        </visual>
        <self_collide>0</self_collide>
        <enable_wind>0</enable_wind>
        <kinematic>0</kinematic>
      </link>
      <joint name='17_21' type='fixed'>
        <pose>0.42 0 0 0 -0 0</pose>
        <parent>Wall_21</parent>
        <child>Wall_17</child>
        <axis>
          <xyz>1 0 0</xyz>
          <limit>
            <lower>-1e+16</lower>
            <upper>1e+16</upper>
          </limit>
        </axis>
      </joint>
      <joint name='17_19' type='fixed'>
        <pose>-0.42 0 0 0 -0 0</pose>
        <parent>Wall_19</parent>
        <child>Wall_17</child>
        <axis>
          <xyz>1 0 0</xyz>
          <limit>
            <lower>-1e+16</lower>
            <upper>1e+16</upper>
          </limit>
        </axis>
      </joint>
      <joint name='17_25' type='fixed'>
        <pose>0 -0.3 0 0 -0 0</pose>
        <parent>Wall_25</parent>
        <child>Wall_17</child>
        <axis>
          <xyz>0 1 0</xyz>
          <limit>
            <lower>-1e+16</lower>
            <upper>1e+16</upper>
          </limit>
        </axis>
      </joint>
      <link name='Wall_19'>
        <pose>-0.41 0 0.192 0 -0 0</pose>
        <inertial>
          <mass>2.223</mass>
          <inertia>
            <ixx>0.0668</ixx>
            <iyy>0.094</iyy>
            <izz>0.0274</izz>
            <ixy>0</ixy>
            <ixz>0</ixz>
            <iyz>0</iyz>
          </inertia>
        </inertial>
        <collision name='Wall_19_Collision'>
          <geometry>
            <box>
              <size>0.02 0.6 0.384</size>
            </box>
          </geometry>
          <max_contacts>10</max_contacts>
          <surface>
            <contact>
              <ode/>
            </contact>
            <bounce/>
            <friction>
              <torsional>
                <ode/>
              </torsional>
              <ode/>
            </friction>
          </surface>
        </collision>
        <visual name='Wall_19_Visual'>
          <geometry>
            <box>
              <size>0.02 0.6 0.384</size>
            </box>
          </geometry>
          <material>
            <script>
              <uri>file://media/materials/scripts/gazebo.material</uri>
              <name>Gazebo/Grey</name>
            </script>
            <ambient>1 0.764706 0.305882 1</ambient>
          </material>
        </visual>
        <self_collide>0</self_collide>
        <enable_wind>0</enable_wind>
        <kinematic>0</kinematic>
      </link>
      <link name='Wall_21'>
        <pose>0.41 0 0.192 0 -0 0</pose>
        <inertial>
          <mass>2.223</mass>
          <inertia>
            <ixx>0.0668</ixx>
            <iyy>0.094</iyy>
            <izz>0.0274</izz>
            <ixy>0</ixy>
            <ixz>0</ixz>
            <iyz>0</iyz>
          </inertia>
        </inertial>
        <collision name='Wall_21_Collision'>
          <geometry>
            <box>
              <size>0.02 0.6 0.384</size>
            </box>
          </geometry>
          <max_contacts>10</max_contacts>
          <surface>
            <contact>
              <ode/>
            </contact>
            <bounce/>
            <friction>
              <torsional>
                <ode/>
              </torsional>
              <ode/>
            </friction>
          </surface>
        </collision>
        <visual name='Wall_21_Visual'>
          <geometry>
            <box>
              <size>0.02 0.6 0.384</size>
            </box>
          </geometry>
          <material>
            <script>
              <uri>file://media/materials/scripts/gazebo.material</uri>
              <name>Gazebo/Grey</name>
            </script>
            <ambient>1 0.764706 0.305882 1</ambient>
          </material>
        </visual>
        <self_collide>0</self_collide>
        <enable_wind>0</enable_wind>
        <kinematic>0</kinematic>
      </link>
      <link name='Wall_23'>
        <pose>0 0 0.374 0 -0 0</pose>
        <inertial>
          <mass>4.8627</mass>
          <inertia>
            <ixx>0.146</ixx>
            <iyy>0.4318</iyy>
            <izz>0.2861</izz>
            <ixy>0</ixy>
            <ixz>0</ixz>
            <iyz>0</iyz>
          </inertia>
        </inertial>
        <collision name='Wall_23_Collision'>
          <geometry>
            <box>
              <size>0.84 0.6 0.02</size>
            </box>
          </geometry>
          <max_contacts>10</max_contacts>
          <surface>
            <contact>
              <ode/>
            </contact>
            <bounce/>
            <friction>
              <torsional>
                <ode/>
              </torsional>
              <ode/>
            </friction>
          </surface>
        </collision>
        <visual name='Wall_23_Visual'>
          <geometry>
            <box>
              <size>0.84 0.6 0.02</size>
            </box>
          </geometry>
          <material>
            <script>
              <uri>file://media/materials/scripts/gazebo.material</uri>
              <name>Gazebo/Grey</name>
            </script>
            <ambient>1 0.764706 0.305882 1</ambient>
          </material>
        </visual>
        <self_collide>0</self_collide>
        <enable_wind>0</enable_wind>
        <kinematic>0</kinematic>
      </link>
      <joint name='23_21' type='fixed'>
        <pose>0.42 0 0 0 -0 0</pose>
        <parent>Wall_21</parent>
        <child>Wall_23</child>
        <axis>
          <xyz>0 0 1</xyz>
          <limit>
            <lower>-1e+16</lower>
            <upper>1e+16</upper>
          </limit>
        </axis>
      </joint>
      <joint name='23_19' type='fixed'>
        <pose>-0.42 0 0 0 -0 0</pose>
        <parent>Wall_19</parent>
        <child>Wall_23</child>
        <axis>
          <xyz>0 0 1</xyz>
          <limit>
            <lower>-1e+16</lower>
            <upper>1e+16</upper>
          </limit>
        </axis>
      </joint>
      <joint name='23_25' type='fixed'>
        <pose>0 -0.3 0 0 -0 0</pose>
        <parent>Wall_25</parent>
        <child>Wall_23</child>
        <axis>
          <xyz>0 0 1</xyz>
          <limit>
            <lower>-1e+16</lower>
            <upper>1e+16</upper>
          </limit>
        </axis>
      </joint>
      <link name='Wall_25'>
        <pose>0 -0.29 0.19 0 -0 0</pose>
        <inertial>
          <mass>3.0651</mass>
          <inertia>
            <ixx>0.037</ixx>
            <iyy>0.1786</iyy>
            <izz>0.2154</izz>
            <ixy>0</ixy>
            <ixz>0</ixz>
            <iyz>0</iyz>
          </inertia>
        </inertial>
        <collision name='Wall_25_Collision'>
          <geometry>
            <box>
              <size>0.836 0.02 0.38</size>
            </box>
          </geometry>
          <max_contacts>10</max_contacts>
          <surface>
            <contact>
              <ode/>
            </contact>
            <bounce/>
            <friction>
              <torsional>
                <ode/>
              </torsional>
              <ode/>
            </friction>
          </surface>
        </collision>
        <visual name='Wall_25_Visual'>
          <geometry>
            <box>
              <size>0.836 0.02 0.38</size>
            </box>
          </geometry>
          <material>
            <script>
              <uri>file://media/materials/scripts/gazebo.material</uri>
              <name>Gazebo/Grey</name>
            </script>
            <ambient>1 0.764706 0.305882 1</ambient>
          </material>
        </visual>
        <self_collide>0</self_collide>
        <enable_wind>0</enable_wind>
        <kinematic>0</kinematic>
      </link>
      <joint name='25_21' type='fixed'>
        <pose>0.42 0 0 0 -0 0</pose>
        <parent>Wall_21</parent>
        <child>Wall_25</child>
        <axis>
          <xyz>0 1 0</xyz>
          <limit>
            <lower>-1e+16</lower>
            <upper>1e+16</upper>
          </limit>
        </axis>
      </joint>
      <joint name='25_19' type='fixed'>
        <pose>-0.42 0 0 0 -0 0</pose>
        <parent>Wall_19</parent>
        <child>Wall_25</child>
        <axis>
          <xyz>0 1 0</xyz>
          <limit>
            <lower>-1e+16</lower>
            <upper>1e+16</upper>
          </limit>
        </axis>
      </joint>
      <static>1</static>
      <pose>3.46841 4.77263 0 0 -0 0</pose>
    </model>
    <model name='brick_wall_hole_3'>
      <static>1</static>
      <pose>-2.64876 0.139728 0 0 -0 0</pose>
      <link name='brick_wall_hole_3'>
        <visual name='brick_wall_hole_3'>
          <geometry>
            <mesh>
              <uri>model://brick_wall_hole_3/brick_wall_hole_3.dae</uri>
            </mesh>
          </geometry>
        </visual>
        <collision name='brick_wall_hole_3'>
          <geometry>
            <mesh>
              <uri>model://brick_wall_hole_3/brick_wall_hole_3.dae</uri>
            </mesh>
          </geometry>
          <max_contacts>10</max_contacts>
          <surface>
            <contact>
              <ode/>
            </contact>
            <bounce/>
            <friction>
              <torsional>
                <ode/>
              </torsional>
              <ode/>
            </friction>
          </surface>
        </collision>
        <self_collide>0</self_collide>
        <enable_wind>0</enable_wind>
        <kinematic>0</kinematic>
      </link>
    </model>
    <model name='brick_wall_lshaped_1'>
      <static>1</static>
      <pose>1.63213 -5.36612 0 0 -0 0</pose>
      <link name='brick_wall_lshaped_1'>
        <visual name='brick_wall_lshaped_1'>
          <geometry>
            <mesh>
              <uri>model://brick_wall_lshaped_1/brick_wall_lshaped_1.dae</uri>
            </mesh>
          </geometry>
        </visual>
        <collision name='brick_wall_lshaped_1'>
          <geometry>
            <mesh>
              <uri>model://brick_wall_lshaped_1/brick_wall_lshaped_1.dae</uri>
            </mesh>
          </geometry>
          <max_contacts>10</max_contacts>
          <surface>
            <contact>
              <ode/>
            </contact>
            <bounce/>
            <friction>
              <torsional>
                <ode/>
              </torsional>
              <ode/>
            </friction>
          </surface>
        </collision>
        <self_collide>0</self_collide>
        <enable_wind>0</enable_wind>
        <kinematic>0</kinematic>
      </link>
    </model>
    <model name='brick_wall_hole_5'>
      <static>1</static>
      <pose>7.54026 3.35958 0 0 -0 0</pose>
      <link name='brick_wall_hole_5'>
        <visual name='brick_wall_hole_5'>
          <geometry>
            <mesh>
              <uri>model://brick_wall_hole_5/brick_wall_hole_5.dae</uri>
            </mesh>
          </geometry>
        </visual>
        <collision name='brick_wall_hole_5'>
          <geometry>
            <mesh>
              <uri>model://brick_wall_hole_5/brick_wall_hole_5.dae</uri>
            </mesh>
          </geometry>
          <max_contacts>10</max_contacts>
          <surface>
            <contact>
              <ode/>
            </contact>
            <bounce/>
            <friction>
              <torsional>
                <ode/>
              </torsional>
              <ode/>
            </friction>
          </surface>
        </collision>
        <self_collide>0</self_collide>
        <enable_wind>0</enable_wind>
        <kinematic>0</kinematic>
      </link>
    </model>
    <model name='brick_wall_lshaped_1_0'>
      <static>1</static>
      <pose>-2.54178 -6.18779 0 0 -0 0</pose>
      <link name='brick_wall_lshaped_1'>
        <visual name='brick_wall_lshaped_1'>
          <geometry>
            <mesh>
              <uri>model://brick_wall_lshaped_1/brick_wall_lshaped_1.dae</uri>
            </mesh>
          </geometry>
        </visual>
        <collision name='brick_wall_lshaped_1'>
          <geometry>
            <mesh>
              <uri>model://brick_wall_lshaped_1/brick_wall_lshaped_1.dae</uri>
            </mesh>
          </geometry>
          <max_contacts>10</max_contacts>
          <surface>
            <contact>
              <ode/>
            </contact>
            <bounce/>
            <friction>
              <torsional>
                <ode/>
              </torsional>
              <ode/>
            </friction>
          </surface>
        </collision>
        <self_collide>0</self_collide>
        <enable_wind>0</enable_wind>
        <kinematic>0</kinematic>
      </link>
    </model>
    <model name='brick_wall_hole_3_0'>
      <static>1</static>
      <pose>4.75234 6.98492 0 0 -0 0</pose>
      <link name='brick_wall_hole_3'>
        <visual name='brick_wall_hole_3'>
          <geometry>
            <mesh>
              <uri>model://brick_wall_hole_3/brick_wall_hole_3.dae</uri>
            </mesh>
          </geometry>
        </visual>
        <collision name='brick_wall_hole_3'>
          <geometry>
            <mesh>
              <uri>model://brick_wall_hole_3/brick_wall_hole_3.dae</uri>
            </mesh>
          </geometry>
          <max_contacts>10</max_contacts>
          <surface>
            <contact>
              <ode/>
            </contact>
            <bounce/>
            <friction>
              <torsional>
                <ode/>
              </torsional>
              <ode/>
            </friction>
          </surface>
        </collision>
        <self_collide>0</self_collide>
        <enable_wind>0</enable_wind>
        <kinematic>0</kinematic>
      </link>
    </model>
    <model name='bookshelf_large'>
      <link name='link_1'>
        <pose>-0.000121 -2.1e-05 0 0 -0 0</pose>
        <visual name='visual'>
          <pose>0 0 0 0 -0 0</pose>
          <geometry>
            <mesh>
              <uri>model://bookshelf_large/meshes/frame.dae</uri>
              <scale>1 1 1</scale>
            </mesh>
          </geometry>
          <material>
            <script>
              <uri>model://bookshelf_large/materials/scripts</uri>
              <uri>model://bookshelf_large/materials/textures</uri>
              <name>bookshelf</name>
            </script>
          </material>
          <cast_shadows>1</cast_shadows>
          <transparency>0</transparency>
        </visual>
        <collision name='collision'>
          <laser_retro>0</laser_retro>
          <max_contacts>10</max_contacts>
          <pose>0 0 0 0 -0 0</pose>
          <geometry>
            <mesh>
              <uri>model://bookshelf_large/meshes/frame.dae</uri>
              <scale>1 1 1</scale>
            </mesh>
          </geometry>
          <surface>
            <contact>
              <ode/>
            </contact>
            <bounce/>
            <friction>
              <torsional>
                <ode/>
              </torsional>
              <ode/>
            </friction>
          </surface>
        </collision>
        <self_collide>0</self_collide>
        <enable_wind>0</enable_wind>
        <kinematic>0</kinematic>
      </link>
      <link name='link_2'>
        <pose>0.000122 2.1e-05 0 0 -0 0</pose>
        <visual name='visual'>
          <pose>0 0 0 0 -0 0</pose>
          <geometry>
            <mesh>
              <uri>model://bookshelf_large/meshes/glass.dae</uri>
              <scale>1 1 1</scale>
            </mesh>
          </geometry>
          <material>
            <lighting>1</lighting>
            <ambient>0.3 0.7 0.8 1</ambient>
            <diffuse>0.3 0.9 0.9 1</diffuse>
            <specular>0.01 0.01 0.01 1</specular>
            <emissive>0 0 0 1</emissive>
          </material>
          <cast_shadows>1</cast_shadows>
          <transparency>0.5</transparency>
        </visual>
        <collision name='collision'>
          <laser_retro>0</laser_retro>
          <max_contacts>10</max_contacts>
          <pose>0 0 0 0 -0 0</pose>
          <geometry>
            <mesh>
              <uri>model://bookshelf_large/meshes/glass.dae</uri>
              <scale>1 1 1</scale>
            </mesh>
          </geometry>
          <surface>
            <contact>
              <ode/>
            </contact>
            <bounce/>
            <friction>
              <torsional>
                <ode/>
              </torsional>
              <ode/>
            </friction>
          </surface>
        </collision>
        <self_collide>0</self_collide>
        <enable_wind>0</enable_wind>
        <kinematic>0</kinematic>
      </link>
      <static>1</static>
      <allow_auto_disable>1</allow_auto_disable>
      <pose>6.39252 -1.24165 0 0 -0 0</pose>
    </model>
    <model name='bookshelf_large_0'>
      <link name='link_1'>
        <pose>-0.000121 -2.1e-05 0 0 -0 0</pose>
        <visual name='visual'>
          <pose>0 0 0 0 -0 0</pose>
          <geometry>
            <mesh>
              <uri>model://bookshelf_large/meshes/frame.dae</uri>
              <scale>1 1 1</scale>
            </mesh>
          </geometry>
          <material>
            <script>
              <uri>model://bookshelf_large/materials/scripts</uri>
              <uri>model://bookshelf_large/materials/textures</uri>
              <name>bookshelf</name>
            </script>
          </material>
          <cast_shadows>1</cast_shadows>
          <transparency>0</transparency>
        </visual>
        <collision name='collision'>
          <laser_retro>0</laser_retro>
          <max_contacts>10</max_contacts>
          <pose>0 0 0 0 -0 0</pose>
          <geometry>
            <mesh>
              <uri>model://bookshelf_large/meshes/frame.dae</uri>
              <scale>1 1 1</scale>
            </mesh>
          </geometry>
          <surface>
            <contact>
              <ode/>
            </contact>
            <bounce/>
            <friction>
              <torsional>
                <ode/>
              </torsional>
              <ode/>
            </friction>
          </surface>
        </collision>
        <self_collide>0</self_collide>
        <enable_wind>0</enable_wind>
        <kinematic>0</kinematic>
      </link>
      <link name='link_2'>
        <pose>0.000122 2.1e-05 0 0 -0 0</pose>
        <visual name='visual'>
          <pose>0 0 0 0 -0 0</pose>
          <geometry>
            <mesh>
              <uri>model://bookshelf_large/meshes/glass.dae</uri>
              <scale>1 1 1</scale>
            </mesh>
          </geometry>
          <material>
            <lighting>1</lighting>
            <ambient>0.3 0.7 0.8 1</ambient>
            <diffuse>0.3 0.9 0.9 1</diffuse>
            <specular>0.01 0.01 0.01 1</specular>
            <emissive>0 0 0 1</emissive>
          </material>
          <cast_shadows>1</cast_shadows>
          <transparency>0.5</transparency>
        </visual>
        <collision name='collision'>
          <laser_retro>0</laser_retro>
          <max_contacts>10</max_contacts>
          <pose>0 0 0 0 -0 0</pose>
          <geometry>
            <mesh>
              <uri>model://bookshelf_large/meshes/glass.dae</uri>
              <scale>1 1 1</scale>
            </mesh>
          </geometry>
          <surface>
            <contact>
              <ode/>
            </contact>
            <bounce/>
            <friction>
              <torsional>
                <ode/>
              </torsional>
              <ode/>
            </friction>
          </surface>
        </collision>
        <self_collide>0</self_collide>
        <enable_wind>0</enable_wind>
        <kinematic>0</kinematic>
      </link>
      <static>1</static>
      <allow_auto_disable>1</allow_auto_disable>
      <pose>5.59936 -4.63684 0 0 -0 0</pose>
    </model>
    <state world_name='default'>
      <sim_time>198 192000000</sim_time>
      <real_time>200 303230551</real_time>
      <wall_time>1742011373 507689826</wall_time>
      <iterations>198192</iterations>
      <model name='Fridge_Cabinet_33x15'>
        <pose>3.46841 4.77263 0 0 -0 0</pose>
        <scale>1 1 1</scale>
        <link name='Wall_17'>
          <pose>3.46841 4.77263 0.01 0 -0 0</pose>
          <velocity>0 0 0 0 -0 0</velocity>
          <acceleration>0 0 0 0 -0 0</acceleration>
          <wrench>0 0 0 0 -0 0</wrench>
        </link>
        <link name='Wall_19'>
          <pose>3.05841 4.77263 0.192 0 -0 0</pose>
          <velocity>0 0 0 0 -0 0</velocity>
          <acceleration>0 0 0 0 -0 0</acceleration>
          <wrench>0 0 0 0 -0 0</wrench>
        </link>
        <link name='Wall_21'>
          <pose>3.87841 4.77263 0.192 0 -0 0</pose>
          <velocity>0 0 0 0 -0 0</velocity>
          <acceleration>0 0 0 0 -0 0</acceleration>
          <wrench>0 0 0 0 -0 0</wrench>
        </link>
        <link name='Wall_23'>
          <pose>3.46841 4.77263 0.374 0 -0 0</pose>
          <velocity>0 0 0 0 -0 0</velocity>
          <acceleration>0 0 0 0 -0 0</acceleration>
          <wrench>0 0 0 0 -0 0</wrench>
        </link>
        <link name='Wall_25'>
          <pose>3.46841 4.48263 0.19 0 -0 0</pose>
          <velocity>0 0 0 0 -0 0</velocity>
          <acceleration>0 0 0 0 -0 0</acceleration>
          <wrench>0 0 0 0 -0 0</wrench>
        </link>
      </model>
      <model name='bookshelf_large'>
        <pose>6.39252 -1.24165 0 0 0 -1.55919</pose>
        <scale>1 1 1</scale>
        <link name='link_1'>
          <pose>6.3925 -1.24153 0 0 0 -1.55919</pose>
          <velocity>0 0 0 0 -0 0</velocity>
          <acceleration>0 0 0 0 -0 0</acceleration>
          <wrench>0 0 0 0 -0 0</wrench>
        </link>
        <link name='link_2'>
          <pose>6.39254 -1.24177 0 0 0 -1.55919</pose>
          <velocity>0 0 0 0 -0 0</velocity>
          <acceleration>0 0 0 0 -0 0</acceleration>
          <wrench>0 0 0 0 -0 0</wrench>
        </link>
      </model>
      <model name='bookshelf_large_0'>
        <pose>5.59936 -4.63684 0 0 0 -2.34379</pose>
        <scale>1 1 1</scale>
        <link name='link_1'>
          <pose>5.59943 -4.63674 0 0 0 -2.34379</pose>
          <velocity>0 0 0 0 -0 0</velocity>
          <acceleration>0 0 0 0 -0 0</acceleration>
          <wrench>0 0 0 0 -0 0</wrench>
        </link>
        <link name='link_2'>
          <pose>5.59929 -4.63694 0 0 0 -2.34379</pose>
          <velocity>0 0 0 0 -0 0</velocity>
          <acceleration>0 0 0 0 -0 0</acceleration>
          <wrench>0 0 0 0 -0 0</wrench>
        </link>
      </model>
      <model name='brick_wall_hole_3'>
        <pose>-2.64876 0.139728 0 0 -0 0</pose>
        <scale>1 1 1</scale>
        <link name='brick_wall_hole_3'>
          <pose>-2.64876 0.139728 0 0 -0 0</pose>
          <velocity>0 0 0 0 -0 0</velocity>
          <acceleration>0 0 0 0 -0 0</acceleration>
          <wrench>0 0 0 0 -0 0</wrench>
        </link>
      </model>
      <model name='brick_wall_hole_3_0'>
        <pose>1.05158 7.53157 0 0 0 -1.57172</pose>
        <scale>1 1 1</scale>
        <link name='brick_wall_hole_3'>
          <pose>1.05158 7.53157 0 0 0 -1.57172</pose>
          <velocity>0 0 0 0 -0 0</velocity>
          <acceleration>0 0 0 0 -0 0</acceleration>
          <wrench>0 0 0 0 -0 0</wrench>
        </link>
      </model>
      <model name='brick_wall_hole_5'>
        <pose>7.54026 3.35958 0 0 -0 0</pose>
        <scale>1 1 1</scale>
        <link name='brick_wall_hole_5'>
          <pose>7.54026 3.35958 0 0 -0 0</pose>
          <velocity>0 0 0 0 -0 0</velocity>
          <acceleration>0 0 0 0 -0 0</acceleration>
          <wrench>0 0 0 0 -0 0</wrench>
        </link>
      </model>
      <model name='brick_wall_lshaped_1'>
        <pose>1.63213 -5.36612 0 0 -0 0</pose>
        <scale>1 1 1</scale>
        <link name='brick_wall_lshaped_1'>
          <pose>1.63213 -5.36612 0 0 -0 0</pose>
          <velocity>0 0 0 0 -0 0</velocity>
          <acceleration>0 0 0 0 -0 0</acceleration>
          <wrench>0 0 0 0 -0 0</wrench>
        </link>
      </model>
      <model name='brick_wall_lshaped_1_0'>
        <pose>-2.54178 -6.18779 0 0 -0 0</pose>
        <scale>1 1 1</scale>
        <link name='brick_wall_lshaped_1'>
          <pose>-2.54178 -6.18779 0 0 -0 0</pose>
          <velocity>0 0 0 0 -0 0</velocity>
          <acceleration>0 0 0 0 -0 0</acceleration>
          <wrench>0 0 0 0 -0 0</wrench>
        </link>
      </model>
      <model name='ground_plane'>
        <pose>0 0 0 0 -0 0</pose>
        <scale>1 1 1</scale>
        <link name='link'>
          <pose>0 0 0 0 -0 0</pose>
          <velocity>0 0 0 0 -0 0</velocity>
          <acceleration>0 0 0 0 -0 0</acceleration>
          <wrench>0 0 0 0 -0 0</wrench>
        </link>
      </model>
      <model name='irb120'>
        <pose>0.715012 2.10804 0.09986 -1.1e-05 -0.00041 -0.405418</pose>
        <scale>1 1 1</scale>
        <link name='EE_egp64'>
          <pose>1.35148 1.93279 0.42469 2.29999 0.694923 1.8066</pose>
          <velocity>-0.00512 -0.016566 -0.027444 -0.003513 0.042731 -0.02976</velocity>
          <acceleration>-6.72482 -12.986 -18.5788 2.65104 -1.27388 -2.07158</acceleration>
          <wrench>-6.7e-05 -0.00013 -0.000186 0 -0 0</wrench>
        </link>
        <link name='base_link'>
          <pose>0.715012 2.10804 0.09986 -1.1e-05 -0.00041 -0.405418</pose>
          <velocity>-0.000211 -0.000645 -0.002565 -0.008691 0.032396 -0.000351</velocity>
          <acceleration>0.196216 -0.219539 4.58792 -1.81653 -0.038324 2.86405</acceleration>
          <wrench>99.35 -111.159 2323 0 -0 0</wrench>
        </link>
        <link name='egp64_finger_left_link'>
          <pose>1.23794 1.95556 0.524114 2.29999 0.694924 1.80659</pose>
          <velocity>-0.000183 -0.012858 -0.022658 -0.003481 0.043031 -0.029881</velocity>
          <acceleration>-2.23163 -9.10456 -13.4916 -0.548364 -1.33647 0.700533</acceleration>
          <wrench>-0.006695 -0.027314 -0.040475 0 -0 0</wrench>
        </link>
        <link name='egp64_finger_right_link'>
          <pose>1.243 1.93963 0.539762 2.29999 0.694925 1.80659</pose>
          <velocity>1.8e-05 -0.012969 -0.022835 -0.003436 0.043483 -0.030077</velocity>
          <acceleration>-1.73822 -9.38853 -13.9515 -0.688924 -0.626758 0.170972</acceleration>
          <wrench>-0.005215 -0.028166 -0.041854 0 -0 0</wrench>
        </link>
        <link name='front_left_wheel'>
          <pose>1.01578 2.251 0.099936 -0.000404 -0.390712 -0.405172</pose>
          <velocity>0.002317 -0.001316 -0.009957 -0.00304 -0.014667 0.001225</velocity>
          <acceleration>0.506668 -1.4361 -4.34295 -3.13338 -0.979602 -1.63125</acceleration>
          <wrench>1.34662 -3.81686 -11.5427 0 -0 0</wrench>
        </link>
        <link name='front_right_wheel'>
          <pose>0.818582 1.79154 0.099911 0.000242 -0.285859 -0.405536</pose>
          <velocity>0.000827 -0.000768 -0.002013 0.005288 0.002804 0.001119</velocity>
          <acceleration>-0.647412 -1.03951 3.83744 -2.70277 0.924633 0.391114</acceleration>
          <wrench>-1.72069 -2.76282 10.1992 0 -0 0</wrench>
        </link>
        <link name='link_1'>
          <pose>0.714929 2.10806 0.27186 -5.2e-05 -0.000394 -0.263323</pose>
          <velocity>0.001792 -9e-05 -0.002564 -0.009791 0.0269 -0.033569</velocity>
          <acceleration>6.6073 5.83076 4.64658 -1.2809 1.30795 -2.21877</acceleration>
          <wrench>20.2646 17.8829 14.2511 0 -0 0</wrench>
        </link>
        <link name='link_2'>
          <pose>0.714823 2.10811 0.56186 -8.3e-05 0.861669 -0.263379</pose>
          <velocity>0.010033 0.002779 -0.002414 -0.009496 0.028315 -0.033014</velocity>
          <acceleration>9.49101 5.73427 3.17419 -1.04915 0.336836 -0.526198</acceleration>
          <wrench>37.1004 22.4153 12.4079 0 -0 0</wrench>
        </link>
        <link name='link_3'>
          <pose>0.912673 2.05478 0.737677 -7.4e-05 0.878724 -0.263361</pose>
          <velocity>0.013347 -0.002098 -0.007496 -0.003789 0.047275 -0.032081</velocity>
          <acceleration>12.0685 2.23916 -2.11124 -0.974305 0.29138 2.06039</acceleration>
          <wrench>35.5298 6.59208 -6.2155 0 -0 0</wrench>
        </link>
        <link name='link_4'>
          <pose>0.96471 2.04076 0.782343 0.052643 0.878718 -0.263365</pose>
          <velocity>0.014531 -0.002904 -0.010345 -0.004845 0.045733 -0.031791</velocity>
          <acceleration>3.79038 -3.5735 -8.01506 -1.51732 -0.628829 0.539777</acceleration>
          <wrench>5.03362 -4.7456 -10.644 0 -0 0</wrench>
        </link>
        <link name='link_5'>
          <pose>1.15078 1.99059 0.549827 0.039136 0.537232 -0.283853</pose>
          <velocity>0.002199 -0.009973 -0.0187 -0.00351 0.041585 -0.029385</velocity>
          <acceleration>0.608633 -5.97681 -10.0141 0.437092 -1.11642 -0.581781</acceleration>
          <wrench>0.332314 -3.26334 -5.46768 0 -0 0</wrench>
        </link>
        <link name='link_6'>
          <pose>1.21016 1.97327 0.512981 -0.055619 0.537231 -0.283858</pose>
          <velocity>-0.000149 -0.012029 -0.021537 -0.003541 0.04249 -0.029666</velocity>
          <acceleration>-1.5539 -8.25919 -12.4962 1.86233 -1.12805 -1.40177</acceleration>
          <wrench>-0.222208 -1.18106 -1.78696 0 -0 0</wrench>
        </link>
        <link name='rear_left_wheel'>
          <pose>0.611447 2.42454 0.099756 -5e-06 -0.48191 -0.405419</pose>
          <velocity>0.001796 -0.000739 -0.004143 -0.001116 -0.001885 -0.000151</velocity>
          <acceleration>0.448429 -0.974604 -1.94693 -0.042533 0.379202 -2.65225</acceleration>
          <wrench>1.19183 -2.5903 -5.17456 0 -0 0</wrench>
        </link>
        <link name='rear_right_wheel'>
          <pose>0.414252 1.96508 0.099803 0.000117 -1.17674 -0.405523</pose>
          <velocity>0.000236 -0.001777 0.012773 0.017787 0.002398 -0.000363</velocity>
          <acceleration>0.226899 -0.788103 27.1174 2.48418 -1.24958 -3.08418</acceleration>
          <wrench>0.603051 -2.09462 72.0725 0 -0 0</wrench>
        </link>
      </model>
      <light name='sun'>
        <pose>0 0 10 0 -0 0</pose>
      </light>
    </state>
    <gui fullscreen='0'>
      <camera name='user_camera'>
        <pose>-0.570843 -2.86315 32.2676 -4.5e-05 1.5698 -0.536651</pose>
        <view_controller>orbit</view_controller>
        <projection_type>perspective</projection_type>
      </camera>
    </gui>
  </world>
</sdf>
